'use client'

import React, { Component, ErrorInfo, ReactNode } from 'react'
import { AlertTriangle, RefreshCw, Home } from 'lucide-react'
import Link from 'next/link'

interface Props {
  children: ReactNode
  fallback?: ReactNode
}

interface State {
  hasError: boolean
  error?: Error
  errorInfo?: ErrorInfo
}

export class ErrorBoundary extends Component<Props, State> {
  constructor(props: Props) {
    super(props)
    this.state = { hasError: false }
  }

  static getDerivedStateFromError(error: Error): State {
    return { hasError: true, error }
  }

  componentDidCatch(error: Error, errorInfo: ErrorInfo) {
    console.error('ErrorBoundary caught an error:', error, errorInfo)
    this.setState({ error, errorInfo })
  }

  render() {
    if (this.state.hasError) {
      if (this.props.fallback) {
        return this.props.fallback
      }

      return (
        <div className="min-h-screen bg-gray-50 flex items-center justify-center px-4">
          <div className="max-w-md w-full bg-white rounded-lg shadow-lg p-6">
            <div className="text-center">
              <div className="mx-auto flex items-center justify-center h-12 w-12 rounded-full bg-red-100 mb-4">
                <AlertTriangle className="h-6 w-6 text-red-600" />
              </div>
              <h3 className="text-lg font-medium text-gray-900 mb-2">
                Something went wrong
              </h3>
              <p className="text-sm text-gray-600 mb-6">
                We encountered an unexpected error. Please try refreshing the page or go back to the homepage.
              </p>
              
              <div className="space-y-3">
                <button
                  onClick={() => window.location.reload()}
                  className="w-full inline-flex items-center justify-center px-4 py-2 border border-transparent text-sm font-medium rounded-md text-white bg-blue-600 hover:bg-blue-700 focus:outline-none focus:ring-2 focus:ring-offset-2 focus:ring-blue-500"
                >
                  <RefreshCw className="h-4 w-4 mr-2" />
                  Refresh Page
                </button>
                
                <Link
                  href="/"
                  className="w-full inline-flex items-center justify-center px-4 py-2 border border-gray-300 text-sm font-medium rounded-md text-gray-700 bg-white hover:bg-gray-50 focus:outline-none focus:ring-2 focus:ring-offset-2 focus:ring-blue-500"
                >
                  <Home className="h-4 w-4 mr-2" />
                  Go Home
                </Link>
              </div>
              
              {process.env.NODE_ENV === 'development' && this.state.error && (
                <details className="mt-6 text-left">
                  <summary className="text-sm font-medium text-gray-700 cursor-pointer">
                    Error Details (Development)
                  </summary>
                  <div className="mt-2 p-3 bg-gray-100 rounded text-xs font-mono text-gray-800 overflow-auto">
                    <div className="mb-2">
                      <strong>Error:</strong> {this.state.error.message}
                    </div>
                    {this.state.error.stack && (
                      <div>
                        <strong>Stack:</strong>
                        <pre className="mt-1 whitespace-pre-wrap">{this.state.error.stack}</pre>
                      </div>
                    )}
                  </div>
                </details>
              )}
            </div>
          </div>
        </div>
      )
    }

    return this.props.children
  }
}

// Hook version for functional components
export function useErrorBoundary() {
  const [hasError, setHasError] = React.useState(false)
  const [error, setError] = React.useState<Error | null>(null)

  React.useEffect(() => {
    const handleError = (event: ErrorEvent) => {
      console.error('Error caught by useErrorBoundary:', event.error)
      setError(event.error)
      setHasError(true)
    }

    const handleUnhandledRejection = (event: PromiseRejectionEvent) => {
      console.error('Unhandled promise rejection caught by useErrorBoundary:', event.reason)
      setError(new Error(event.reason))
      setHasError(true)
    }

    window.addEventListener('error', handleError)
    window.addEventListener('unhandledrejection', handleUnhandledRejection)

    return () => {
      window.removeEventListener('error', handleError)
      window.removeEventListener('unhandledrejection', handleUnhandledRejection)
    }
  }, [])

  const resetError = React.useCallback(() => {
    setHasError(false)
    setError(null)
  }, [])

  return { hasError, error, resetError }
}

// Higher-order component for error boundaries
export function withErrorBoundary<P extends object>(
  Component: React.ComponentType<P>,
  fallback?: ReactNode
) {
  return function WithErrorBoundary(props: P) {
    return (
      <ErrorBoundary fallback={fallback}>
        <Component {...props} />
      </ErrorBoundary>
    )
  }
} 